<mujoco model="turtlebot3_burger">
  <compiler angle="radian" meshdir="./" autolimits="true"/>
  <statistic meansize="0.0563245" extent="0.284544" center="-0.0314095 -1.28119e-06 0.0998247"/>
  <asset>
    <mesh name="burger_base" file="burger_base.stl" scale="0.001 0.001 0.001"/>
    <mesh name="left_tire" file="left_tire.stl" scale="0.001 0.001 0.001"/>
    <mesh name="right_tire" file="right_tire.stl" scale="0.001 0.001 0.001"/>
    <mesh name="lds" file="lds.stl" scale="0.001 0.001 0.001"/>
  </asset>
  <worldbody>
    <body name="base_footprint">
      <body name="base_link" pos="0 0 0.01">
        <inertial pos="0 0 0" quat="0.994532 -0.0072214 -0.0815456 -0.0648458" mass="0.825735" diaginertia="0.00221987 0.00211778 0.00200059"/>
        <geom pos="-0.032 0 0" type="mesh" contype="0" conaffinity="0" group="1" density="0" mesh="burger_base"/>
        <body name="wheel_left_link" pos="0 0.08 0.023" quat="0.707388 -0.706825 0 0">
          <inertial pos="0 0 0" quat="-0.000890159 0.706886 0.000889646 0.707326" mass="0.0284989" diaginertia="2.07126e-05 1.11924e-05 1.11756e-05"/>
          <joint name="wheel_left_joint" pos="0 0 0" axis="0 0 1"/>
          <geom quat="0.707388 0.706825 0 0" type="mesh" contype="0" conaffinity="0" group="1" density="0" mesh="left_tire"/>
        </body>
        <body name="wheel_right_link" pos="0 -0.08 0.023" quat="0.707388 -0.706825 0 0">
          <inertial pos="0 0 0" quat="-0.000890159 0.706886 0.000889646 0.707326" mass="0.0284989" diaginertia="2.07126e-05 1.11924e-05 1.11756e-05"/>
          <joint name="wheel_right_joint" pos="0 0 0" axis="0 0 1"/>
          <geom quat="0.707388 0.706825 0 0" type="mesh" contype="0" conaffinity="0" group="1" density="0" mesh="right_tire"/>
        </body>
        <body name="caster_back_link" pos="-0.081 0 -0.004" quat="0.707388 -0.706825 0 0">
          <inertial pos="0 0 0" mass="0.005" diaginertia="0.001 0.001 0.001"/>
          <geom size="0.015 0.0045 0.01" pos="0 0.001 0" type="box"/>
        </body>
        <body name="imu_link" pos="-0.032 0 0.068"/>
        <body name="base_scan" pos="-0.032 0 0.172">
          <inertial pos="0 0 0" mass="0.114" diaginertia="0.001 0.001 0.001"/>
          <geom type="mesh" contype="0" conaffinity="0" group="1" density="0" mesh="lds"/>
        </body>
      </body>
    </body>
  </worldbody>
</mujoco>
