<mujoco model="turtlebot3_burger">
  <compiler angle="radian" meshdir="./" autolimits="true"/>
  <statistic meansize="0.0480478" extent="0.284544" center="-0.0316037 -1.28119e-06 0.0998247"/>

  <asset>
    <!-- sky and plane -->
    <texture type="skybox" builtin="gradient" width="2048" height="2048"/>
    <texture name="grid" type="2d" builtin="checker" width="512" height="512" rgb1=".1 .2 .3" rgb2=".2 .3 .4"/>
    <material name="grid" texture="grid" texrepeat="1 1" texuniform="true" reflectance=".2"/>

    <!-- robot -->
    <mesh name="burger_base" file="burger_base.stl" scale="0.001 0.001 0.001"/>
    <mesh name="left_tire" file="left_tire.stl" scale="0.001 0.001 0.001"/>
    <mesh name="right_tire" file="right_tire.stl" scale="0.001 0.001 0.001"/>
    <mesh name="lds" file="lds.stl" scale="0.001 0.001 0.001"/>
  </asset>

  <worldbody>
    <geom pos="-0.032 0 0.01" type="mesh" contype="0" conaffinity="0" group="1" density="0" mesh="burger_base"/>
    <!-- <geom size="0.07 0.07 0.0715" pos="-0.032 0 0.08" type="box"/> -->
    <geom size="0.015 0.0045 0.01" pos="-0.081 7.96327e-07 0.005" quat="0.707388 -0.706825 0 0" type="box"/>
    <geom pos="-0.032 0 0.182" type="mesh" contype="0" conaffinity="0" group="1" density="0" mesh="lds"/>
    <!-- <geom size="0.055 0.01575" pos="-0.017 0 0.1755" type="cylinder"/> -->
    <body name="wheel_left_link" pos="0 0.08 0.033" quat="0.707388 -0.706825 0 0">
      <inertial pos="0 0 0" quat="-0.000890159 0.706886 0.000889646 0.707326" mass="0.0284989" diaginertia="2.07126e-05 1.11924e-05 1.11756e-05"/>
      <joint name="wheel_left_joint" pos="0 0 0" axis="0 0 1"/>
      <geom quat="0.707388 0.706825 0 0" type="mesh" contype="0" conaffinity="0" group="1" density="0" mesh="left_tire"/>
      <!-- <geom size="0.033 0.009" type="cylinder"/> -->
    </body>
    <body name="wheel_right_link" pos="0 -0.08 0.033" quat="0.707388 -0.706825 0 0">
      <inertial pos="0 0 0" quat="-0.000890159 0.706886 0.000889646 0.707326" mass="0.0284989" diaginertia="2.07126e-05 1.11924e-05 1.11756e-05"/>
      <joint name="wheel_right_joint" pos="0 0 0" axis="0 0 1"/>
      <geom quat="0.707388 0.706825 0 0" type="mesh" contype="0" conaffinity="0" group="1" density="0" mesh="right_tire"/>
      <!-- <geom size="0.033 0.009" type="cylinder"/> -->
    </body>
  </worldbody>

</mujoco>
