<mujoco model="turtlebot3_burger">
  <compiler angle="radian" meshdir="./" autolimits="true"/>
  <statistic meansize="0.0480478" extent="0.284544" center="-0.0316037 -1.28119e-06 0.0998247"/>

  <asset>
    <!-- sky and plane -->
    <texture type="skybox" builtin="gradient" width="2048" height="2048"/>
    <texture name="grid" type="2d" builtin="checker" width="512" height="512" rgb1=".1 .2 .3" rgb2=".2 .3 .4"/>
    <material name="grid" texture="grid" texrepeat="1 1" texuniform="true" reflectance=".2"/>

    <!-- robot -->
    <mesh name="burger_base" file="robot/burger_base.stl" scale="0.001 0.001 0.001"/>
    <mesh name="left_tire" file="robot/left_tire.stl" scale="0.001 0.001 0.001"/>
    <mesh name="right_tire" file="robot/right_tire.stl" scale="0.001 0.001 0.001"/>
    <mesh name="lds" file="robot/lds.stl" scale="0.001 0.001 0.001"/>
  </asset>

  <worldbody>
    <!-- sky and plane -->
    <light cutoff="100" diffuse="1 1 1" dir="0 0 -1.3" directional="true" exponent="1" pos="0 0 1.3" specular="0.1 0.1 0.1"/>
	  <geom name="floor" type="plane" size="100 100 .2" material="grid"/>

    <!-- robot -->
    <body name="robot" pos="0 0 0">
      <freejoint/>

      <body name="base" pos="0 0 0">
        <inertial pos="0 0 0" mass="8.2573504e-01"
          fullinertia="2.2124416e-03 2.1193702e-03 2.0064271e-03 -1.2294101e-05 3.4938785e-05 -5.0120904e-06"/>
        <geom pos="0 0 0" type="mesh" mesh="burger_base"/>
      </body>

      <geom size="0.015 0.0045 0.01" pos="-4.90000e-02 7.96327e-07 -5.00000e-03" quat="0.707388 -0.706825 0 0" type="box"/>

      <body name="sensor">
        <inertial pos="0 0 0" mass="0.114" fullinertia="0.001 0.001 0.001 0 0 0"/>
        <geom pos="0 0 0.172" type="mesh" mesh="lds"/>
      </body>
      
      <body name="wheel_left_link" pos="0.032 0.08 0.023" quat="0.707388 -0.706825 0 0">
        <inertial pos="0 0 0" mass="0.0284989"
          fullinertia="1.11756e-05 1.11924e-05 2.07126e-05 -4.2369783e-11 -5.9381719e-09 -1.4400107e-11"/>
        <joint name="wheel_left_joint" pos="0 0 0" axis="0 0 1"/>
        <geom quat="0.707388 0.706825 0 0" type="mesh" mesh="left_tire"/>
      </body>

      <body name="wheel_right_link" pos="0.032 -0.08 0.023" quat="0.707388 -0.706825 0 0">
        <inertial pos="0 0 0" mass="0.0284989"
          fullinertia="1.11756e-05 1.11924e-05 2.07126e-05 -4.2369783e-11 -5.9381719e-09 -1.4400107e-11"/>
        <joint name="wheel_right_joint" pos="0 0 0" axis="0 0 1"/>
        <geom quat="0.707388 0.706825 0 0" type="mesh" mesh="right_tire"/>
      </body>

      <!-- <body name="wheel_left_link" pos="0.032 0.08 0.023" quat="0.707388 -0.706825 0 0">
        <inertial pos="0 0 0" quat="-0.000890159 0.706886 0.000889646 0.707326" mass="0.0284989"
          fullinertia="2.07126e-05 1.11924e-05 1.11756e-05"/>
        <joint name="wheel_left_joint" pos="0 0 0" axis="0 0 1"/>
        <geom quat="0.707388 0.706825 0 0" type="mesh" mesh="left_tire"/>
      </body>

      <body name="wheel_right_link" pos="0.032 -0.08 0.023" quat="0.707388 -0.706825 0 0">
        <inertial pos="0 0 0" quat="-0.000890159 0.706886 0.000889646 0.707326" mass="0.0284989"
          fullinertia="2.07126e-05 1.11924e-05 1.11756e-05"/>
        <joint name="wheel_right_joint" pos="0 0 0" axis="0 0 1"/>
        <geom quat="0.707388 0.706825 0 0" type="mesh" mesh="right_tire"/>
      </body> -->
    </body>

    <!-- notes remove quat from inertial? fix diag for wheels -->

  </worldbody>

  <actuator>
    <motor name="left_motor" joint="wheel_left_joint" gear="1"/>
    <motor name="right_motor" joint="wheel_right_joint" gear="1"/>
  </actuator>

</mujoco>
